2025-05-04 16:30:42,786 - ERROR - Erro ao gerar o dashboard:
Traceback (most recent call last):
  File "C:\Users\fabio\anaconda3\Lib\site-packages\pandas\core\indexes\base.py", line 3805, in get_loc
    return self._engine.get_loc(casted_key)
           ^^^^^^^^^^^^^^^^^^^^^^^^^^^^^^^^
  File "index.pyx", line 167, in pandas._libs.index.IndexEngine.get_loc
  File "index.pyx", line 196, in pandas._libs.index.IndexEngine.get_loc
  File "pandas\\_libs\\hashtable_class_helper.pxi", line 7081, in pandas._libs.hashtable.PyObjectHashTable.get_item
  File "pandas\\_libs\\hashtable_class_helper.pxi", line 7089, in pandas._libs.hashtable.PyObjectHashTable.get_item
KeyError: 'Entidade'

The above exception was the direct cause of the following exception:

Traceback (most recent call last):
  File "g:\estudos\Penglai\BI\gera_relatorio_shao.py", line 22, in <module>
    df_clientes = df[df["Entidade"] == "Cliente"]
                     ~~^^^^^^^^^^^^
  File "C:\Users\fabio\anaconda3\Lib\site-packages\pandas\core\frame.py", line 4102, in __getitem__
    indexer = self.columns.get_loc(key)
              ^^^^^^^^^^^^^^^^^^^^^^^^^
  File "C:\Users\fabio\anaconda3\Lib\site-packages\pandas\core\indexes\base.py", line 3812, in get_loc
    raise KeyError(key) from err
KeyError: 'Entidade'

2025-05-04 16:31:38,376 - ERROR - Erro ao gerar o dashboard:
Traceback (most recent call last):
  File "C:\Users\fabio\anaconda3\Lib\site-packages\pandas\core\indexes\base.py", line 3805, in get_loc
    return self._engine.get_loc(casted_key)
           ^^^^^^^^^^^^^^^^^^^^^^^^^^^^^^^^
  File "index.pyx", line 167, in pandas._libs.index.IndexEngine.get_loc
  File "index.pyx", line 196, in pandas._libs.index.IndexEngine.get_loc
  File "pandas\\_libs\\hashtable_class_helper.pxi", line 7081, in pandas._libs.hashtable.PyObjectHashTable.get_item
  File "pandas\\_libs\\hashtable_class_helper.pxi", line 7089, in pandas._libs.hashtable.PyObjectHashTable.get_item
KeyError: 'Entidade'

The above exception was the direct cause of the following exception:

Traceback (most recent call last):
  File "g:\estudos\Penglai\BI\gera_relatorio_shao.py", line 22, in <module>
    df_clientes = df[df["Entidade"] == "Cliente"]
                     ~~^^^^^^^^^^^^
  File "C:\Users\fabio\anaconda3\Lib\site-packages\pandas\core\frame.py", line 4102, in __getitem__
    indexer = self.columns.get_loc(key)
              ^^^^^^^^^^^^^^^^^^^^^^^^^
  File "C:\Users\fabio\anaconda3\Lib\site-packages\pandas\core\indexes\base.py", line 3812, in get_loc
    raise KeyError(key) from err
KeyError: 'Entidade'

2025-05-04 16:32:00,055 - ERROR - Erro ao gerar o dashboard:
Traceback (most recent call last):
  File "C:\Users\fabio\anaconda3\Lib\site-packages\pandas\core\indexes\base.py", line 3805, in get_loc
    return self._engine.get_loc(casted_key)
           ^^^^^^^^^^^^^^^^^^^^^^^^^^^^^^^^
  File "index.pyx", line 167, in pandas._libs.index.IndexEngine.get_loc
  File "index.pyx", line 196, in pandas._libs.index.IndexEngine.get_loc
  File "pandas\\_libs\\hashtable_class_helper.pxi", line 7081, in pandas._libs.hashtable.PyObjectHashTable.get_item
  File "pandas\\_libs\\hashtable_class_helper.pxi", line 7089, in pandas._libs.hashtable.PyObjectHashTable.get_item
KeyError: 'Entidade'

The above exception was the direct cause of the following exception:

Traceback (most recent call last):
  File "g:\estudos\Penglai\BI\gera_relatorio_shao.py", line 22, in <module>
    df_clientes = df[df["Entidade"] == "Cliente"]
                     ~~^^^^^^^^^^^^
  File "C:\Users\fabio\anaconda3\Lib\site-packages\pandas\core\frame.py", line 4102, in __getitem__
    indexer = self.columns.get_loc(key)
              ^^^^^^^^^^^^^^^^^^^^^^^^^
  File "C:\Users\fabio\anaconda3\Lib\site-packages\pandas\core\indexes\base.py", line 3812, in get_loc
    raise KeyError(key) from err
KeyError: 'Entidade'

2025-05-04 16:33:41,021 - ERROR - Erro ao gerar o dashboard:
Traceback (most recent call last):
  File "g:\estudos\Penglai\BI\gera_relatorio_shao.py", line 134, in <module>
    print("\u2705 Dashboard gerado com sucesso!")
  File "C:\Users\fabio\anaconda3\Lib\encodings\cp1252.py", line 19, in encode
    return codecs.charmap_encode(input,self.errors,encoding_table)[0]
           ^^^^^^^^^^^^^^^^^^^^^^^^^^^^^^^^^^^^^^^^^^^^^^^^^^^^^^^
UnicodeEncodeError: 'charmap' codec can't encode character '\u2705' in position 0: character maps to <undefined>

2025-05-04 16:36:25,510 - ERROR - Erro ao gerar o dashboard:
Traceback (most recent call last):
  File "g:\estudos\Penglai\BI\gera_relatorio_shao.py", line 134, in <module>
    print("\u2705 Dashboard gerado com sucesso!")
  File "C:\Users\fabio\anaconda3\Lib\encodings\cp1252.py", line 19, in encode
    return codecs.charmap_encode(input,self.errors,encoding_table)[0]
           ^^^^^^^^^^^^^^^^^^^^^^^^^^^^^^^^^^^^^^^^^^^^^^^^^^^^^^^
UnicodeEncodeError: 'charmap' codec can't encode character '\u2705' in position 0: character maps to <undefined>

2025-05-04 16:38:14,095 - ERROR - Erro ao gerar o dashboard:
Traceback (most recent call last):
  File "g:\estudos\Penglai\BI\gera_relatorio_shao.py", line 134, in <module>
    print("\u2705 Dashboard gerado com sucesso!")
  File "C:\Users\fabio\anaconda3\Lib\encodings\cp1252.py", line 19, in encode
    return codecs.charmap_encode(input,self.errors,encoding_table)[0]
           ^^^^^^^^^^^^^^^^^^^^^^^^^^^^^^^^^^^^^^^^^^^^^^^^^^^^^^^
UnicodeEncodeError: 'charmap' codec can't encode character '\u2705' in position 0: character maps to <undefined>

